Workbook

Sheet Orders
A1: Client Name | B1: Date | C1: Number | D1: المحافطة | E1: المنطقة | F1: Social | G1: Order Details | H1: Quantity | I1: Price | J1: Discount | K1: Total | L1: Deposit | M1: Deposit Method | N1: The Rest | O1: Done | P1: Processed | Q1: Payed | R1: Payment Method | S1: Balance | T1: Delivery | U1: Delivery By | V1: Column 22 | W1: Column 23 | X1: Column 24
A2: Hana | B2: 46096 | D2: القليوبية | E2: العبور | F2: I | G2: أسفار الكتاب المقدس | H2: 1 | I2: =IF(G2="", "", IFERROR(VLOOKUP(G2, Products!A:F, 4, FALSE), "")) -> 850 | J2: 100 | K2: =(H2*I2)-J2 -> 750 | L2: 750 | M2: Instapay | N2: =K2-L2 -> 0 | O2: TRUE | P2: TRUE | S2: =N2-Q2 -> 0 | T2: TRUE | V2: FALSE | W2: FALSE | X2: FALSE
A3: جوزيف | B3: 46097 | D3: القاهرة | E3: عزبة النخل | G3: أسبوع الالام | H3: 3 | I3: =IF(G3="", "", IFERROR(VLOOKUP(G3, Products!A:F, 4, FALSE), "")) -> 80 | J3: 0 | K3: =(H3*I3)-J3 -> 240 | L3: 120 | M3: VF | N3: =K3-L3 -> 120 | O3: TRUE | P3: TRUE | Q3: 200 | R3: Visa post | S3: 0 | T3: TRUE | U3: بريد | V3: FALSE | W3: FALSE | X3: FALSE
A4: جوزيف | B4: 46097 | D4: القاهرة | E4: عزبة النخل | G4: خيمة الاجتماع | H4: 1 | I4: =IF(G4="", "", IFERROR(VLOOKUP(G4, Products!A:F, 4, FALSE), "")) -> 80 | J4: 0 | K4: =(H4*I4)-J4 -> 80 | N4: =K4-L4 -> 80 | O4: TRUE | P4: TRUE | Q4: 80 | R4: Visa post | S4: 0 | T4: TRUE | U4: بريد | V4: FALSE | W4: FALSE | X4: FALSE
A5: جوزيف | B5: 46097 | D5: القاهرة | E5: عزبة النخل | G5: Todo List | H5: 6 | I5: =IF(G5="", "", IFERROR(VLOOKUP(G5, Products!A:F, 4, FALSE), "")) -> 23 | J5: 0 | K5: =(H5*I5)-J5 -> 138 | N5: =K5-L5 -> 138 | O5: TRUE | P5: TRUE | Q5: 140 | R5: Visa post | S5: 0 | T5: TRUE | U5: بريد | V5: FALSE | W5: FALSE | X5: FALSE
A6: مريم مجدي عبد الملك | B6: 46097 | D6: الغربية | E6: طنطا | G6: أسبوع الالام | H6: 3 | I6: =IF(G6="", "", IFERROR(VLOOKUP(G6, Products!A:F, 4, FALSE), "")) -> 80 | J6: 0 | K6: =(H6*I6)-J6 -> 240 | L6: 120 | M6: Instapay | N6: =K6-L6 -> 120 | O6: TRUE | P6: TRUE | Q6: 120 | R6: Visa post | S6: =N6-Q6 -> 0 | T6: TRUE | U6: بريد | V6: FALSE | W6: FALSE | X6: FALSE
A7: Hana | B7: 46097 | D7: القليوبية | E7: العبور | F7: T | G7: خيمة الاجتماع | H7: 6 | I7: =IF(G7="", "", IFERROR(VLOOKUP(G7, Products!A:F, 4, FALSE), "")) -> 80 | J7: 0 | K7: =(H7*I7)-J7 -> 480 | L7: 480 | M7: Instapay | N7: =K7-L7 -> 0 | O7: TRUE | P7: TRUE | S7: =N7-Q7 -> 0 | T7: TRUE | V7: FALSE | W7: FALSE | X7: FALSE
A8: Hana | B8: 46097 | D8: القليوبية | E8: العبور | G8: أحاد الصوم | H8: 6 | I8: =IF(G8="", "", IFERROR(VLOOKUP(G8, Products!A:F, 4, FALSE), "")) -> 80 | J8: 0 | K8: =(H8*I8)-J8 -> 480 | L8: 480 | M8: Instapay | N8: =K8-L8 -> 0 | O8: TRUE | P8: TRUE | S8: =N8-Q8 -> 0 | T8: TRUE | V8: FALSE | W8: FALSE | X8: FALSE
A9: Hana | B9: 46097 | D9: القليوبية | E9: العبور | G9: أسبوع الالام | H9: 6 | I9: =IF(G9="", "", IFERROR(VLOOKUP(G9, Products!A:F, 4, FALSE), "")) -> 80 | J9: 0 | K9: =(H9*I9)-J9 -> 480 | L9: 480 | M9: Instapay | N9: =K9-L9 -> 0 | O9: TRUE | P9: TRUE | S9: =N9-Q9 -> 0 | T9: TRUE | V9: FALSE | W9: FALSE | X9: FALSE
A10: Hana | B10: 46097 | D10: القليوبية | E10: العبور | G10: أيات يونان | H10: 3 | I10: =IF(G10="", "", IFERROR(VLOOKUP(G10, Products!A:F, 4, FALSE), "")) -> 100 | J10: 0 | K10: =(H10*I10)-J10 -> 300 | L10: 300 | M10: Instapay | N10: =K10-L10 -> 0 | O10: TRUE | P10: TRUE | S10: =N10-Q10 -> 0 | T10: TRUE | V10: FALSE | W10: FALSE | X10: FALSE
A11: Mr. Ramy | B11: 46097 | D11: الجيزة | E11: اول الهرم | G11: أحاد الصوم | H11: 6 | I11: =IF(G11="", "", IFERROR(VLOOKUP(G11, Products!A:F, 4, FALSE), "")) -> 80 | J11: 0 | K11: =(H11*I11)-J11 -> 480 | L11: 480 | M11: Instapay | N11: =K11-L11 -> 0 | O11: TRUE | P11: TRUE | S11: =N11-Q11 -> 0 | T11: TRUE | V11: FALSE | W11: FALSE | X11: FALSE
A12: Tirvina | B12: 46097 | D12: القاهرة | E12: مصر القديمة | G12: أسبوع الالام | H12: 14 | I12: =IF(G12="", "", IFERROR(VLOOKUP(G12, Products!A:F, 4, FALSE), "")) -> 80 | J12: 0 | K12: =(H12*I12)-J12 -> 1120 | L12: 1120 | M12: Instapay | N12: =K12-L12 -> 0 | O12: TRUE | P12: TRUE | S12: =N12-Q12 -> 0 | T12: TRUE | V12: FALSE | W12: FALSE | X12: FALSE
A13: Youstina adel | B13: 46097 | D13: القاهرة | E13: عين شمس | G13: أحاد الصوم | H13: 1 | I13: =IF(G13="", "", IFERROR(VLOOKUP(G13, Products!A:F, 4, FALSE), "")) -> 80 | J13: 0 | K13: =(H13*I13)-J13 -> 80 | L13: 80 | M13: Instapay | N13: =K13-L13 -> 0 | O13: TRUE | P13: TRUE | S13: =N13-Q13 -> 0 | T13: TRUE | V13: FALSE | W13: FALSE | X13: FALSE
A14: Youstina adel | B14: 46097 | D14: القاهرة | E14: عين شمس | G14: أسبوع الالام | H14: 2 | I14: =IF(G14="", "", IFERROR(VLOOKUP(G14, Products!A:F, 4, FALSE), "")) -> 80 | J14: 0 | K14: =(H14*I14)-J14 -> 160 | L14: 160 | M14: Instapay | N14: =K14-L14 -> 0 | O14: TRUE | P14: TRUE | S14: =N14-Q14 -> 0 | T14: TRUE | V14: FALSE | W14: FALSE | X14: FALSE
A15: ابراهيم ميلاد | B15: 46098 | D15: اسيوط | G15: أسبوع الالام | H15: 10 | I15: =IF(G15="", "", IFERROR(VLOOKUP(G15, Products!A:F, 4, FALSE), "")) -> 80 | J15: 0 | K15: =(H15*I15)-J15 -> 800 | L15: 500 | M15: VF | N15: =K15-L15 -> 300 | O15: TRUE | P15: TRUE | Q15: 300 | R15: Visa post | S15: =N15-Q15 -> 0 | T15: TRUE | U15: بريد | V15: FALSE | W15: FALSE | X15: FALSE
A16: اسحب نبيل | B16: 46098 | D16: اسيوط | G16: أسبوع الالام | H16: 3 | I16: =IF(G16="", "", IFERROR(VLOOKUP(G16, Products!A:F, 4, FALSE), "")) -> 80 | J16: 0 | K16: =(H16*I16)-J16 -> 240 | L16: 120 | M16: VF | N16: =K16-L16 -> 120 | O16: TRUE | P16: TRUE | Q16: 120 | R16: Visa post | S16: =N16-Q16 -> 0 | T16: TRUE | U16: بريد | V16: FALSE | W16: FALSE | X16: FALSE
A17: دميانة ابراهيم | B17: 46098 | D17: الجيزة | E17: امبابة | G17: أسبوع الالام | H17: 4 | I17: =IF(G17="", "", IFERROR(VLOOKUP(G17, Products!A:F, 4, FALSE), "")) -> 80 | J17: 0 | K17: =(H17*I17)-J17 -> 320 | L17: 320 | M17: Instapay | N17: =K17-L17 -> 0 | O17: TRUE | P17: TRUE | S17: =N17-Q17 -> 0 | T17: TRUE | V17: FALSE | W17: FALSE | X17: FALSE
A18: Mr. Ramy | B18: 46098 | D18: الجيزة | E18: اول الهرم | F18: F | G18: أسبوع الالام | H18: 6 | I18: =IF(G18="", "", IFERROR(VLOOKUP(G18, Products!A:F, 4, FALSE), "")) -> 80 | J18: 0 | K18: =(H18*I18)-J18 -> 480 | L18: 480 | M18: Instapay | N18: =K18-L18 -> 0 | O18: TRUE | P18: TRUE | S18: =N18-Q18 -> 0 | T18: TRUE | V18: FALSE | W18: FALSE | X18: FALSE
A19: ايمان صبحي | B19: 46099 | D19: الجيزة | E19: وراق | G19: أسبوع الالام | H19: 7 | I19: =IF(G19="", "", IFERROR(VLOOKUP(G19, Products!A:F, 4, FALSE), "")) -> 80 | J19: 0 | K19: =(H19*I19)-J19 -> 560 | L19: 560 | M19: Instapay | N19: =K19-L19 -> 0 | O19: TRUE | P19: TRUE | S19: =N19-Q19 -> 0 | T19: TRUE | V19: FALSE | W19: FALSE | X19: FALSE
A20: بيشوي رمزي | B20: 46099 | D20: منوفية | G20: أسبوع الالام | H20: 1 | I20: =IF(G20="", "", IFERROR(VLOOKUP(G20, Products!A:F, 4, FALSE), "")) -> 80 | J20: 0 | K20: =(H20*I20)-J20 -> 80 | L20: 80 | M20: Instapay | N20: =K20-L20 -> 0 | O20: TRUE | P20: TRUE | S20: =N20-Q20 -> 0 | T20: TRUE | V20: FALSE | W20: FALSE | X20: FALSE
A21: حنان فرج | B21: 46099 | D21: القاهرة | E21: ١٥ مايو | G21: أسبوع الالام | H21: 2 | I21: =IF(G21="", "", IFERROR(VLOOKUP(G21, Products!A:F, 4, FALSE), "")) -> 80 | J21: 0 | K21: =(H21*I21)-J21 -> 160 | L21: 160 | M21: Instapay | N21: =K21-L21 -> 0 | O21: TRUE | P21: TRUE | S21: =N21-Q21 -> 0 | T21: TRUE | V21: FALSE | W21: FALSE | X21: FALSE
A22: مريم لمعي | B22: 46099 | D22: القاهرة | E22: التجمع | G22: أسبوع الالام | H22: 13 | I22: =IF(G22="", "", IFERROR(VLOOKUP(G22, Products!A:F, 4, FALSE), "")) -> 80 | J22: 0 | K22: =(H22*I22)-J22 -> 1040 | L22: 500 | M22: VF | N22: =K22-L22 -> 540 | O22: TRUE | P22: TRUE | Q22: 540 | R22: Visa post | S22: =N22-Q22 -> 0 | T22: TRUE | U22: بريد | V22: FALSE | W22: FALSE | X22: FALSE
A23: مينا سمير | B23: 46099 | D23: القاهرة | E23: مصر والسودان | G23: أسبوع الالام | H23: 1 | I23: =IF(G23="", "", IFERROR(VLOOKUP(G23, Products!A:F, 4, FALSE), "")) -> 80 | J23: 0 | K23: =(H23*I23)-J23 -> 80 | L23: 80 | M23: Instapay | N23: =K23-L23 -> 0 | O23: TRUE | P23: TRUE | S23: =N23-Q23 -> 0 | T23: TRUE | V23: FALSE | W23: FALSE | X23: FALSE
A24: نرمين عاطف | B24: 46099 | D24: البحر الاحمر | G24: أسبوع الالام | H24: 4 | I24: =IF(G24="", "", IFERROR(VLOOKUP(G24, Products!A:F, 4, FALSE), "")) -> 80 | J24: 0 | K24: 250 | L24: 250 | M24: Instapay | N24: =K24-L24 -> 0 | O24: FALSE | P24: FALSE | S24: =N24-Q24 -> 0 | T24: FALSE | U24: Reject | V24: FALSE | W24: FALSE | X24: FALSE
A25: نرمين عاطف | B25: 46099 | D25: البحر الاحمر | G25: أحاد الصوم | H25: 4 | I25: =IF(G25="", "", IFERROR(VLOOKUP(G25, Products!A:F, 4, FALSE), "")) -> 80 | J25: 0 | K25: 250 | L25: 250 | M25: Instapay | N25: =K25-L25 -> 0 | O25: FALSE | P25: FALSE | S25: =N25-Q25 -> 0 | T25: FALSE | U25: Reject | V25: FALSE | W25: FALSE | X25: FALSE
A26: هناء جرجس سوريال | B26: 46099 | D26: القاهرة | E26: حلوان | G26: أسبوع الالام | H26: 6 | I26: =IF(G26="", "", IFERROR(VLOOKUP(G26, Products!A:F, 4, FALSE), "")) -> 80 | J26: 0 | K26: =(H26*I26)-J26 -> 480 | L26: 480 | M26: Instapay | N26: =K26-L26 -> 0 | O26: TRUE | P26: TRUE | S26: =N26-Q26 -> 0 | T26: TRUE | V26: FALSE | W26: FALSE | X26: FALSE
A27: آن نبيل | B27: 46100 | D27: القاهرة | E27: شبرا | G27: أسبوع الالام | H27: 6 | I27: =IF(G27="", "", IFERROR(VLOOKUP(G27, Products!A:F, 4, FALSE), "")) -> 80 | J27: 0 | K27: =(H27*I27)-J27 -> 480 | L27: 240 | M27: Instapay | N27: =K27-L27 -> 240 | O27: TRUE | P27: TRUE | Q27: 240 | R27: Cash | S27: =N27-Q27 -> 0 | T27: TRUE | U27: اسكوتر | V27: FALSE | W27: FALSE | X27: FALSE
A28: القس تداؤس | B28: 46100 | D28: اسيوط | G28: أسبوع الالام | H28: 6 | I28: =IF(G28="", "", IFERROR(VLOOKUP(G28, Products!A:F, 4, FALSE), "")) -> 80 | J28: 0 | K28: =(H28*I28)-J28 -> 480 | L28: 300 | M28: Instapay | N28: =K28-L28 -> 180 | O28: TRUE | P28: TRUE | Q28: 180 | R28: Visa post | S28: =N28-Q28 -> 0 | T28: TRUE | U28: بريد | V28: FALSE | W28: FALSE | X28: FALSE
A29: ايريني عادل | B29: 46100 | D29: القاهرة | E29: مدينة نصر | G29: أسبوع الالام | H29: 3 | I29: =IF(G29="", "", IFERROR(VLOOKUP(G29, Products!A:F, 4, FALSE), "")) -> 80 | J29: 0 | K29: =(H29*I29)-J29 -> 240 | L29: 240 | M29: Instapay | N29: =K29-L29 -> 0 | O29: TRUE | P29: TRUE | S29: =N29-Q29 -> 0 | T29: TRUE | V29: FALSE | W29: FALSE | X29: FALSE
A30: بيتر ملك | B30: 46100 | D30: القاهرة | E30: حدايق القبة | G30: أسبوع الالام | H30: 6 | I30: =IF(G30="", "", IFERROR(VLOOKUP(G30, Products!A:F, 4, FALSE), "")) -> 80 | J30: 0 | K30: =(H30*I30)-J30 -> 480 | L30: 480 | M30: Instapay | N30: =K30-L30 -> 0 | O30: TRUE | P30: TRUE | S30: =N30-Q30 -> 0 | T30: TRUE | V30: FALSE | W30: FALSE | X30: FALSE
A31: ثروت عاطف | B31: 46100 | D31: الجيزة | E31: 6 اكتوبر | G31: أسبوع الالام | H31: 3 | I31: =IF(G31="", "", IFERROR(VLOOKUP(G31, Products!A:F, 4, FALSE), "")) -> 80 | J31: 0 | K31: =(H31*I31)-J31 -> 240 | L31: 240 | M31: Instapay | N31: =K31-L31 -> 0 | O31: TRUE | P31: TRUE | S31: =N31-Q31 -> 0 | T31: TRUE | V31: FALSE | W31: FALSE | X31: FALSE
A32: رانيا عبده | B32: 46100 | D32: اسكندرية | G32: أسبوع الالام | H32: 4 | I32: =IF(G32="", "", IFERROR(VLOOKUP(G32, Products!A:F, 4, FALSE), "")) -> 80 | J32: 0 | K32: =(H32*I32)-J32 -> 320 | L32: 200 | M32: Instapay | N32: =K32-L32 -> 120 | O32: TRUE | P32: TRUE | Q32: 120 | R32: Cash | S32: =N32-Q32 -> 0 | T32: TRUE | U32: اسكوتر | V32: FALSE | W32: FALSE | X32: FALSE
A33: سامح سعد | B33: 46100 | D33: القاهرة | E33: شبرا | G33: أسبوع الالام | H33: 4 | I33: =IF(G33="", "", IFERROR(VLOOKUP(G33, Products!A:F, 4, FALSE), "")) -> 80 | J33: 0 | K33: =(H33*I33)-J33 -> 320 | L33: 160 | M33: Instapay | N33: =K33-L33 -> 160 | O33: TRUE | P33: TRUE | Q33: 160 | R33: Instapay | S33: =N33-Q33 -> 0 | T33: TRUE | V33: FALSE | W33: FALSE | X33: FALSE
A34: شيري امجد | B34: 46100 | D34: القاهرة | E34: حلوان | G34: أسبوع الالام | H34: 10 | I34: =IF(G34="", "", IFERROR(VLOOKUP(G34, Products!A:F, 4, FALSE), "")) -> 80 | J34: 0 | K34: =(H34*I34)-J34 -> 800 | L34: 400 | M34: Instapay | N34: =K34-L34 -> 400 | O34: TRUE | P34: TRUE | Q34: 400 | R34: Instapay | S34: =N34-Q34 -> 0 | T34: TRUE | V34: FALSE | W34: FALSE | X34: FALSE
A35: صموئيل اشرف | B35: 46100 | D35: القاهرة | E35: حدايق القبة | G35: أسبوع الالام | H35: 2 | I35: =IF(G35="", "", IFERROR(VLOOKUP(G35, Products!A:F, 4, FALSE), "")) -> 80 | J35: 0 | K35: =(H35*I35)-J35 -> 160 | L35: 160 | M35: Instapay | N35: =K35-L35 -> 0 | O35: TRUE | P35: TRUE | S35: =N35-Q35 -> 0 | T35: TRUE | V35: FALSE | W35: FALSE | X35: FALSE
A36: كيرلس | B36: 46100 | D36: بني سويف | G36: أسبوع الالام | H36: 4 | I36: =IF(G36="", "", IFERROR(VLOOKUP(G36, Products!A:F, 4, FALSE), "")) -> 80 | J36: 0 | K36: =(H36*I36)-J36 -> 320 | L36: 100 | M36: VF | N36: =K36-L36 -> 220 | O36: TRUE | P36: TRUE | Q36: 220 | R36: Visa post | S36: =N36-Q36 -> 0 | T36: TRUE | U36: بريد | V36: FALSE | W36: FALSE | X36: FALSE
A37: كيرلس | B37: 46100 | D37: بني سويف | G37: أحاد الصوم | H37: 2 | I37: =IF(G37="", "", IFERROR(VLOOKUP(G37, Products!A:F, 4, FALSE), "")) -> 80 | J37: 0 | K37: =(H37*I37)-J37 -> 160 | L37: 150 | M37: VF | N37: =K37-L37 -> 10 | O37: TRUE | P37: TRUE | Q37: 10 | R37: Visa post | S37: =N37-Q37 -> 0 | T37: TRUE | U37: بريد | V37: FALSE | W37: FALSE | X37: FALSE
A38: ليليان | B38: 46100 | D38: القاهرة | E38: المعادي | G38: أسبوع الالام | H38: 5 | I38: =IF(G38="", "", IFERROR(VLOOKUP(G38, Products!A:F, 4, FALSE), "")) -> 80 | J38: 0 | K38: =(H38*I38)-J38 -> 400 | L38: 400 | M38: Instapay | N38: =K38-L38 -> 0 | O38: TRUE | P38: TRUE | S38: =N38-Q38 -> 0 | T38: TRUE | V38: FALSE | W38: FALSE | X38: FALSE
A39: مريم سعد | B39: 46100 | D39: القاهرة | E39: شبرا | G39: أسبوع الالام | H39: 3 | I39: =IF(G39="", "", IFERROR(VLOOKUP(G39, Products!A:F, 4, FALSE), "")) -> 80 | J39: 0 | K39: =(H39*I39)-J39 -> 240 | L39: 120 | M39: Cash | N39: =K39-L39 -> 120 | O39: TRUE | P39: TRUE | Q39: 120 | R39: Cash | S39: =N39-Q39 -> 0 | T39: TRUE | U39: اسكوتر | V39: FALSE | W39: FALSE | X39: FALSE
A40: منى رمزي | B40: 46100 | D40: جيزة | G40: أسبوع الالام | H40: 4 | I40: =IF(G40="", "", IFERROR(VLOOKUP(G40, Products!A:F, 4, FALSE), "")) -> 80 | J40: 0 | K40: =(H40*I40)-J40 -> 320 | L40: 320 | M40: Instapay | N40: =K40-L40 -> 0 | O40: TRUE | P40: TRUE | S40: =N40-Q40 -> 0 | T40: TRUE | V40: FALSE | W40: FALSE | X40: FALSE
...

Sheet Expenses
A1: مصاريف ادارية
A2: المصروف | B2: بيان | C2: تاريخ
A3: 200 | B3: نت لمريم | C3: 46147
A4: 1750 | B4: 500 شنط قماش | C4: 46149
A5: 45 | B5: باقي مواصلات لسارة
A6: 200 | B6: توكتوك
A7: 50 | B7: شمع وصاروخ
A8: 100 | B8: بكرة اسكوتش
A9: 70 | B9: توكتوك اسكوتش
A10: 160 | B10: توكتوك اوردرات
A11: 200 | B11: مواصلات مريم
A12: 120 | B12: بيتر | C12: 46183
A13: 150 | B13: بيتر | C13: 46187
A14: 80 | B14: بيتر | C14: 46188
A15: 145 | B15: مشتريات | C15: ١٦/٦
A16: 70 | B16: شحن اوردر هناء
A17: 800 | B17: 10 ورشة اسبوع الالام
A18: 0 | B18: 4 مجاميع ورشة بولس
A19: 175 | B19: مشتريات | C19: ١٦/٦
A20: 100 | B20: توكتوك | C20: ١٦/٦
A21: 15 | B21: ارضاء عميلة | C21: ١٧/٦
A22: 55 | B22: سلوتب | C22: ١٧/٦
A23: 150 | B23: توكتوك | C23: ١٧/٦
A24: 40 | B24: توكتوك | C24: ١٩/٦
A25: 40 | B25: توكتوك | C25: ٢١/٦
A26: 200 | B26: نت | C26: ١٦/٦
A27: 336 | B27: مشتريات | C27: ١٨/٦
A28: 650 | B28: Capcut | C28: 22/6
A29: 200 | B29: Net | C29: 27/6
A30: 110 | B30: شحن | C30: =IF(A30<>"", IF(C30="", TODAY(), C30), "") -> 46204
A31: 240 | B31: اوردر اتلغى | C31: =IF(A31<>"", IF(C31="", TODAY(), C31), "") -> 46211
A32: 1200 | B32: نوتة كتاب مقدس | C32: =IF(A32<>"", IF(C32="", TODAY(), C32), "") -> 46215
A33: 85 | B33: شحن اوردر | C33: =IF(A33<>"", IF(C33="", TODAY(), C33), "") -> 46215
A34: 160 | B34: اوردر ملغي | C34: =IF(A34<>"", IF(C34="", TODAY(), C34), "") -> 46215
A35: 320 | B35: توكتوك | C35: =IF(A35<>"", IF(C35="", TODAY(), C35), "") -> 46216
A36: 1500 | B36: ارضاء عميلة | C36: =IF(A36<>"", IF(C36="", TODAY(), C36), "") -> 46226
A37: 1000 | B37: ديبوزيت فورمة | C37: =IF(A37<>"", IF(C37="", TODAY(), C37), "") -> 46226
A38: 700 | B38: باقي فورمة | C38: =IF(A38<>"", IF(C38="", TODAY(), C38), "") -> 46231
A39: 115 | B39: كيلو فلاير | C39: =IF(A39<>"", IF(C39="", TODAY(), C39), "") -> 46231
A40: 100 | B40: سلوتب | C40: =IF(A40<>"", IF(C40="", TODAY(), C40), "") -> 46231
...

Sheet Clients
A1: العمود 1 | B1: Phone | C1: المحافظة | D1: المنطقة | E1: العنوان بالتفصيل | F1: اسم الكنيسة
A2: الورشة | B2: 0 | E2: الكرنفال
A3: Mr. Ramy | C3: الجيزة | D3: الهرم | E3: اول
A4: Hana | C4: القليوبية | D4: العبور
A5: Tirvina | C5: القاهرة | D5: مصر القديمة
A6: Youstina adel | C6: القاهرة | D6: عين شمس
A7: مريم مجدي عبد الملك | C7: الغربية | D7: طنطا
A8: جوزيف | C8: القاهرة | D8: عزبة النخل
A9: اسحب نبيل | C9: أسيوط
A10: دميانة ابراهيم | C10: الجيزة | D10: إمبابة
A11: ابراهيم ميلاد | C11: أسيوط
A12: مينا سمير | C12: القاهرة | D12: مصر والسودان
A13: بيشوي رمزي | C13: المنوفية
A14: حنان فرج | C14: القاهرة | D14: 15 مايو
A15: نرمين عاطف | C15: البحر الأحمر
A16: مريم لمعي | C16: القاهرة | D16: التجمع
A17: هناء جرجس سوريال | C17: القاهرة | D17: حلوان
A18: ايمان صبحي | C18: الجيزة | E18: وراق
A19: ايريني عادل | C19: القاهرة | D19: مدينة نصر
A20: آن نبيل | C20: القاهرة | D20: شبرا
A21: نادر | C21: الجيزة | E21: حدايق الاهرام
A22: ليليان | C22: القاهرة | D22: المعادي
A23: كيرلس | C23: بني سويف
A24: القس تداؤس | C24: أسيوط
A25: منى رمزي | C25: الجيزة
A26: ثروت عاطف | C26: الجيزة | D26: أكتوبر
A27: بيتر ملك | C27: القاهرة | D27: حدايق القبة
A28: شيري امجد | C28: القاهرة | D28: حلوان
A29: سامح سعد | C29: القاهرة | D29: شبرا
A30: صموئيل اشرف | C30: القاهرة | D30: حدايق القبة
A31: رانيا عبده | C31: الإسكندرية
A32: مريم سعد | C32: القاهرة | D32: شبرا
A33: نرمين ابراهيم | C33: الإسكندرية | E33: اسكندرية
A34: الفريد كمال | C34: أسيوط
A35: ميشيل يوسف | C35: بني سويف
A36: ليديا سيف | C36: القليوبية | D36: العبور
A37: مونيكا | C37: OUT
A38: مرثا | C38: OUT
A39: نيرمين سمير | C39: أسوان
A40: ابونا | C40: سوهاج
...

Sheet Products
A1: ProductName | B1: Type | C1: شراء | D1: بيع | E1: كوست | F1: ربح | G1: الاوردرات | H1: الوارد | I1: المخزن | K1: شراء | L1: بيع
A2: Bible Note | B2: Brand | C2: 12 | D2: 30 | E2: 5 | F2: =D2-E2-C2 -> 13 | G2: =SUMIF(Table1[[#ALL],[Order Details]],"Bible Note",Table1[[#ALL],[Quantity]]) -> 279 | H2: =Stock!Z54 -> 383 | I2: =H2-G2 -> 104 | K2: =I2*C2 -> 1248 | L2: =I2*D2 -> 3120
A3: Basic Note | B3: Brand | C3: 16 | D3: 18 | E3: 0 | F3: =D3-E3-C3 -> 2 | G3: =SUMIF(Table1[[#ALL],[Order Details]],"Basic Note",Table1[[#ALL],[Quantity]]) -> 10 | H3: =Stock!T54 -> 70 | I3: =H3-G3 -> 60 | K3: =I3*C3 -> 960 | L3: =I3*D3 -> 1080
A4: Todo List | B4: Brand | C4: 10 | D4: 23 | E4: 5 | F4: =D4-E4-C4 -> 8 | G4: =SUMIF(Table1[[#ALL],[Order Details]],"Todo List",Table1[[#ALL],[Quantity]]) -> 17 | H4: =Stock!Q54 -> 83 | I4: =H4-G4 -> 66 | K4: =I4*C4 -> 660 | L4: =I4*D4 -> 1518
A5: Tracker Note | B5: Brand | C5: 12 | D5: 30 | E5: 5 | F5: =D5-E5-C5 -> 13 | G5: =SUMIF(Table1[[#ALL],[Order Details]],"Tracker Note",Table1[[#ALL],[Quantity]]) -> 11 | H5: =Stock!W54 -> 68 | I5: =H5-G5 -> 57 | K5: =I5*C5 -> 684 | L5: =I5*D5 -> 1710
A6: Rule | B6: Brand | C6: 0 | D6: 15 | E6: 5 | F6: =D6-E6-C6 -> 10 | G6: =SUMIF(Table1[[#ALL],[Order Details]],"Rule",Table1[[#ALL],[Quantity]]) -> 0 | H6: =Stock!K166 -> 0 | I6: =H6-G6 -> 0 | K6: =I6*C6 -> 0 | L6: =I6*D6 -> 0
A7: Coster | B7: Brand | C7: 0 | D7: 20 | E7: 5 | F7: =D7-E7-C7 -> 15 | H7: =Stock!B82 -> 10 | I7: =H7-G7 -> 10 | K7: =I7*C7 -> 0 | L7: =I7*D7 -> 200
A8: Stand Mobile | B8: Brand | C8: 0 | D8: 0 | F8: =D8-E8-C8 -> 0 | H8: 0 | I8: =H8-G8 -> 0 | K8: =I8*C8 -> 0 | L8: =I8*D8 -> 0
A9: ميدالية ميلاد | B9: Brand | C9: 0 | D9: 0 | F9: =D9-E9-C9 -> 0 | H9: 8 | I9: =H9-G9 -> 8 | K9: =I9*C9 -> 0 | L9: =I9*D9 -> 0
A10: ستاند ميلاد | B10: Brand | C10: 0 | D10: 0 | F10: =D10-E10-C10 -> 0 | H10: 5 | I10: =H10-G10 -> 5 | K10: =I10*C10 -> 0 | L10: =I10*D10 -> 0
A11: شجرة | B11: Brand | C11: 0 | D11: 0 | F11: =D11-E11-C11 -> 0 | H11: 11 | I11: =H11-G11 -> 11 | K11: =I11*C11 -> 0 | L11: =I11*D11 -> 0
A12: بازل ميلاد | B12: Brand | C12: 0 | D12: 0 | F12: =D12-E12-C12 -> 0 | H12: 7 | I12: =H12-G12 -> 7 | K12: =I12*C12 -> 0 | L12: =I12*D12 -> 0
A13: كارت حضور 4 | B13: Workshop | C13: 1 | D13: 3 | E13: 0 | F13: =D13-E13-C13 -> 2 | G13: =SUMIF(Table1[[#ALL],[Order Details]],"كارت حضور 4",Table1[[#ALL],[Quantity]]) -> 3045 | H13: =Stock!N166 -> 3045 | I13: =H13-G13 -> 0 | K13: =I13*C13 -> 0 | L13: =I13*D13 -> 0
A14: كارت حضور 5 | B14: Workshop | C14: 1 | D14: 4 | E14: 0 | F14: =D14-E14-C14 -> 3 | G14: =SUMIF(Table1[[#ALL],[Order Details]],"كارت حضور 5",Table1[[#ALL],[Quantity]]) -> 200 | H14: =Stock!Q166 -> 200 | I14: =H14-G14 -> 0 | K14: =I14*C14 -> 0 | L14: =I14*D14 -> 0
A15: كارت حضور 8 | B15: Workshop | C15: 1 | D15: 5 | E15: 0 | F15: =D15-E15-C15 -> 4 | G15: =SUMIF(Table1[[#ALL],[Order Details]],"كارت حضور 8",Table1[[#ALL],[Quantity]]) -> 0 | H15: =Stock!T166 -> 0 | I15: =H15-G15 -> 0 | K15: =I15*C15 -> 0 | L15: =I15*D15 -> 0
A16: كارت حضور 12 | B16: Workshop | C16: 1 | D16: 5 | E16: 0 | F16: =D16-E16-C16 -> 4 | G16: =SUMIF(Table1[[#ALL],[Order Details]],"كارت حضور 12",Table1[[#ALL],[Quantity]]) -> 40 | H16: =Stock!W166 -> 50 | I16: =H16-G16 -> 10 | K16: =I16*C16 -> 10 | L16: =I16*D16 -> 50
A17: كارت حضور العدراء | B17: Workshop | C17: 1 | D17: 5 | E17: 0 | F17: =D17-E17-C17 -> 4 | G17: =SUMIF(Table1[[#ALL],[Order Details]],"كارت حضور العدراء",Table1[[#ALL],[Quantity]]) -> 480 | H17: =Stock!Z166 -> 1000 | I17: =H17-G17 -> 520 | K17: =I17*C17 -> 520 | L17: =I17*D17 -> 2600
A18: ختم حضور | B18: Workshop | C18: 50 | D18: 100 | E18: 5 | F18: =D18-E18-C18 -> 45 | G18: =SUMIF(Table1[[#ALL],[Order Details]],"ختم حضور",Table1[[#ALL],[Quantity]]) -> 28 | H18: =Stock!Z139 -> 28 | I18: =H18-G18 -> 0 | K18: =I18*C18 -> 0 | L18: =I18*D18 -> 0
A19: باكيدچ | B19: Workshop | C19: 1450 | D19: 2000 | E19: 50 | F19: =D19-E19-C19 -> 500 | G19: =SUMIF(Table1[[#ALL],[Order Details]],"باكيدچ",Table1[[#ALL],[Quantity]]) -> 1 | H19: 1 | I19: =H19-G19 -> 0 | K19: =I19*C19 -> 0 | L19: =I19*D19 -> 0
A20: File | B20: Digital | C20: 0 | D20: 100 | E20: 0 | F20: =D20-E20-C20 -> 100 | G20: =SUMIF(Table1[[#ALL],[Order Details]],"File",Table1[[#ALL],[Quantity]]) -> 10 | H20: 0 | I20: 0 | K20: =I20*C20 -> 0 | L20: =I20*D20 -> 0
A21: أسبوع الالام | B21: Workshop | C21: 30 | D21: 80 | E21: 5 | F21: =D21-E21-C21 -> 45 | G21: =SUMIF(Table1[[#ALL],[Order Details]],"أسبوع الالام",Table1[[#ALL],[Quantity]]) -> 478 | H21: =Stock!B26 -> 478 | I21: =H21-G21 -> 0 | K21: =I21*C21 -> 0 | L21: =I21*D21 -> 0
A22: استيكر اسبوع الالام | B22: Workshop | C22: 10 | D22: 20 | E22: 5 | F22: =D22-E22-C22 -> 5 | G22: =SUMIF(Table1[[#ALL],[Order Details]],"استيكر اسبوع الالام",Table1[[#ALL],[Quantity]]) -> 0 | H22: =Stock!E26 -> 13 | I22: =H22-G22 -> 13 | K22: =I22*C22 -> 130 | L22: =I22*D22 -> 260
A23: أحاد الصوم | B23: Workshop | C23: 30 | D23: 80 | E23: 5 | F23: =D23-E23-C23 -> 45 | G23: =SUMIF(Table1[[#ALL],[Order Details]],"أحاد الصوم",Table1[[#ALL],[Quantity]]) -> 58 | H23: =Stock!H26 -> 61 | I23: =H23-G23 -> 3 | K23: =I23*C23 -> 90 | L23: =I23*D23 -> 240
A24: استيكر أحاد الصوم | B24: Workshop | C24: 10 | D24: 20 | E24: 5 | F24: =D24-E24-C24 -> 5 | G24: =SUMIF(Table1[[#ALL],[Order Details]],"استيكر أحاد الصوم",Table1[[#ALL],[Quantity]]) -> 0 | H24: =Stock!K26 -> 3 | I24: =H24-G24 -> 3 | K24: =I24*C24 -> 30 | L24: =I24*D24 -> 60
A25: القيامة ابتدائي | B25: Workshop | C25: 30 | D25: 80 | E25: 5 | F25: =D25-E25-C25 -> 45 | G25: =SUMIF(Table1[[#ALL],[Order Details]],"القيامة ابتدائي",Table1[[#ALL],[Quantity]]) -> 126 | H25: =Stock!N26 -> 138 | I25: =H25-G25 -> 12 | K25: =I25*C25 -> 360 | L25: =I25*D25 -> 960
A26: استيكر القيامة ابتدائي | B26: Workshop | C26: 10 | D26: 20 | E26: 5 | F26: =D26-E26-C26 -> 5 | G26: =SUMIF(Table1[[#ALL],[Order Details]],"استيكر القيامة ابتدائي",Table1[[#ALL],[Quantity]]) -> 0 | H26: =Stock!Q26 -> 1 | I26: =H26-G26 -> 1 | K26: =I26*C26 -> 10 | L26: =I26*D26 -> 20
A27: القيامة شباب | B27: Workshop | C27: 30 | D27: 80 | E27: 5 | F27: =D27-E27-C27 -> 45 | G27: =SUMIF(Table1[[#ALL],[Order Details]],"القيامة شباب",Table1[[#ALL],[Quantity]]) -> 478 | H27: =Stock!T26 -> 481 | I27: =H27-G27 -> 3 | K27: =I27*C27 -> 90 | L27: =I27*D27 -> 240
A28: أستيكر القيامة شباب | B28: Workshop | C28: 10 | D28: 20 | E28: 5 | F28: =D28-E28-C28 -> 5 | G28: =SUMIF(Table1[[#ALL],[Order Details]],"أستيكر القيامة شباب",Table1[[#ALL],[Quantity]]) -> 0 | H28: =Stock!W26 -> 15 | I28: =H28-G28 -> 15 | K28: =I28*C28 -> 150 | L28: =I28*D28 -> 300
A29: القيامة فردية 300جرام | B29: Workshop | C29: 9 | D29: 15 | E29: 1 | F29: =D29-E29-C29 -> 5 | G29: =SUMIF(Table1[[#ALL],[Order Details]],"القيامة فردية 300جرام",Table1[[#ALL],[Quantity]]) -> 490 | H29: =Stock!Z26 -> 499 | I29: =H29-G29 -> 9 | K29: =I29*C29 -> 81 | L29: =I29*D29 -> 135
A30: القيامة فردية 150جرام | B30: Workshop | C30: 8 | D30: 12 | E30: 1 | F30: =D30-E30-C30 -> 3 | G30: =SUMIF(Table1[[#ALL],[Order Details]],"القيامة فردية 150جرام",Table1[[#ALL],[Quantity]]) -> 0 | H30: 0 | I30: =H30-G30 -> 0 | K30: =I30*C30 -> 0 | L30: =I30*D30 -> 0
A31: القيامة فردية 80جرام | B31: Workshop | C31: 5 | D31: 9 | E31: 1 | F31: =D31-E31-C31 -> 3 | G31: =SUMIF(Table1[[#ALL],[Order Details]],"القيامة فردية 80جرام",Table1[[#ALL],[Quantity]]) -> 0 | H31: 0 | I31: =H31-G31 -> 0 | K31: =I31*C31 -> 0 | L31: =I31*D31 -> 0
A32: أيات يونان | B32: Workshop | C32: 50 | D32: 100 | E32: 5 | F32: =D32-E32-C32 -> 45 | G32: =SUMIF(Table1[[#ALL],[Order Details]],"أيات يونان",Table1[[#ALL],[Quantity]]) -> 3 | H32: 3 | I32: =H32-G32 -> 0 | K32: =I32*C32 -> 0 | L32: =I32*D32 -> 0
A33: أسفار الكتاب المقدس | B33: Workshop | C33: 650 | D33: 850 | E33: 5 | F33: =D33-E33-C33 -> 195 | G33: =SUMIF(Table1[[#ALL],[Order Details]],"أسفار الكتاب المقدس",Table1[[#ALL],[Quantity]]) -> 19 | H33: =Stock!H54 -> 21 | I33: =H33-G33 -> 2 | K33: =I33*C33 -> 1300 | L33: =I33*D33 -> 1700
A34: خيمة الاجتماع | B34: Workshop | C34: 30 | D34: 80 | E34: 5 | F34: =D34-E34-C34 -> 45 | G34: =SUMIF(Table1[[#ALL],[Order Details]],"خيمة الاجتماع",Table1[[#ALL],[Quantity]]) -> 128 | H34: =Stock!K54 -> 133 | I34: =H34-G34 -> 5 | K34: =I34*C34 -> 150 | L34: =I34*D34 -> 400
A35: أحاد الخماسين | B35: Workshop | C35: 30 | D35: 80 | E35: 5 | F35: =D35-E35-C35 -> 45 | G35: =SUMIF(Table1[[#ALL],[Order Details]],"أحاد الخماسين",Table1[[#ALL],[Quantity]]) -> 94 | H35: =Stock!N54 -> 101 | I35: =H35-G35 -> 7 | K35: =I35*C35 -> 210 | L35: =I35*D35 -> 560
A36: رحلات بولس خشب | B36: Workshop | C36: 200 | D36: 400 | E36: 5 | F36: =D36-E36-C36 -> 195 | G36: =SUMIF(Table1[[#ALL],[Order Details]],"رحلات بولس خشب",Table1[[#ALL],[Quantity]]) -> 120 | H36: =Stock!Z82 -> 142 | I36: =H36-G36 -> 22 | K36: =I36*C36 -> 4400 | L36: =I36*D36 -> 8800
A37: رحلات بولس ورق | B37: Workshop | C37: 130 | D37: 200 | E37: 5 | F37: =D37-E37-C37 -> 65 | G37: =SUMIF(Table1[[#ALL],[Order Details]],"رحلات بولس ورق",Table1[[#ALL],[Quantity]]) -> 55 | H37: =Stock!AC82 -> 63 | I37: =H37-G37 -> 8 | K37: =I37*C37 -> 1040 | L37: =I37*D37 -> 1600
A38: رحلات بولس خرايط | B38: Workshop | C38: 100 | D38: 200 | E38: 5 | F38: =D38-E38-C38 -> 95 | G38: =SUMIF(Table1[[#ALL],[Order Details]],"رحلات بولس خرايط",Table1[[#ALL],[Quantity]]) -> 0 | H38: =Stock!B112 -> 0 | I38: =H38-G38 -> 0 | K38: =I38*C38 -> 0 | L38: =I38*D38 -> 0
A39: استيكر خيمة الاجتماع | B39: Workshop | C39: 10 | D39: 20 | E39: 5 | F39: =D39-E39-C39 -> 5 | G39: =SUMIF(Table1[[#ALL],[Order Details]],"استيكر خيمة الاجتماع",Table1[[#ALL],[Quantity]]) -> 0 | H39: =Stock!B166 -> 0 | I39: =H39-G39 -> 0 | K39: =I39*C39 -> 0 | L39: =I39*D39 -> 0
A40: استيكر خماسين | B40: Workshop | C40: 10 | D40: 20 | E40: 5 | F40: =D40-E40-C40 -> 5 | G40: =SUMIF(Table1[[#ALL],[Order Details]],"استيكر خماسين",Table1[[#ALL],[Quantity]]) -> 0 | H40: =Stock!K82 -> 9 | I40: =H40-G40 -> 9 | K40: =I40*C40 -> 90 | L40: =I40*D40 -> 180
...

Sheet Stock
B2: اسبوع الالام | E2: استيكر اسبوع الالام | H2: أحاد الصوم | K2: استيكر أحاد الصوم | N2: القيامة ابتدائي | Q2: استيكر القيامة ابتدائي | T2: القيامة شباب | W2: أستيكر القيامة شباب | Z2: القيامة فردية 300جرام | AC2: استيكر فردية
B3: عدد | C3: تاريخ | E3: عدد | F3: تاريخ | H3: عدد | I3: تاريخ | K3: عدد | L3: تاريخ | N3: عدد | O3: تاريخ | Q3: عدد | R3: تاريخ | T3: عدد | U3: تاريخ | W3: عدد | X3: تاريخ | Z3: عدد | AA3: تاريخ | AC3: عدد | AD3: تاريخ
B4: 6 | C4: 46102 | E4: 3 | F4: 46146 | H4: 6 | I4: 46102 | K4: 3 | L4: 46146 | N4: 50 | O4: 46111 | Q4: 1 | R4: 46146 | T4: 50 | U4: 46113 | W4: 15 | X4: 46146 | Z4: 150 | AA4: 46111 | AC4: 20 | AD4: 46146
B5: 20 | C5: 46102 | E5: 10 | F5: 46271 | H5: 10 | I5: 46102 | N5: 50 | O5: 46113 | T5: 50 | U5: 46116 | Z5: 120 | AA5: 46116
B6: 100 | C6: 46103 | H6: 20 | I6: 46103 | N6: 20 | O6: 46126 | T6: 100 | U6: 46116 | Z6: 150 | AA6: 46116
B7: 25 | C7: 46103 | H7: 12 | I7: 46105 | N7: 3 | O7: 46127 | T7: 100 | U7: 46118 | Z7: 50 | AA7: 46121
B8: 50 | C8: 46104 | H8: 5 | I8: 46194 | N8: 1 | O8: 46216 | T8: 50 | U8: 46119 | Z8: 20 | AA8: 46130
B9: 125 | C9: 46104 | H9: 5 | I9: 46215 | N9: 14 | O9: 46217 | T9: 30 | U9: 46126 | Z9: 9 | AA9: 46146
B10: 27 | C10: 46105 | H10: 3 | I10: 46216 | T10: 20 | U10: 46127
B11: 49 | C11: 46106 | T11: 30 | U11: 46127
B12: 12 | C12: 46107 | T12: 20 | U12: 46130
B13: 20 | C13: 46109 | T13: 10 | U13: 46132
B14: 10 | C14: 46111 | T14: 10 | U14: 46138
B15: 10 | C15: 46112 | T15: 10 | U15: 46183
B16: 10 | C16: 46112 | T16: 1 | U16: 46194
B17: 10 | C17: 46271
B18: 4 | C18: 46029
B26: =SUM(B4:B25) -> 478 | E26: =SUM(E4:E25) -> 13 | H26: =SUM(H4:H25) -> 61 | K26: =SUM(K4:K25) -> 3 | N26: =SUM(N4:N25) -> 138 | Q26: =SUM(Q4:Q25) -> 1 | T26: =SUM(T4:T25) -> 481 | W26: =SUM(W4:W25) -> 15 | Z26: =SUM(Z4:Z25) -> 499 | AC26: =SUM(AC4:AC25) -> 20
B29: القيامة فردية 80جرام | E29: ايات يونان | H29: أسفار الكتاب المقدس | K29: خيمة الاجتماع | N29: أحاد الخماسين | Q29: To do list | T29: Basic note | W29: Tracker note | Z29: Bible note | AC29: نوتة ميلاد
B30: عدد | C30: تاريخ | E30: عدد | F30: تاريخ | H30: عدد | I30: تاريخ | K30: عدد | L30: تاريخ | N30: عدد | O30: تاريخ | Q30: عدد | R30: تاريخ | T30: عدد | U30: تاريخ | W30: عدد | X30: تاريخ | Z30: عدد | AA30: تاريخ | AC30: عدد | AD30: تاريخ
E31: 3 | F31: 46101 | H31: 1 | I31: 46103 | K31: 6 | L31: 46102 | N31: 10 | O31: 46132 | Q31: 6 | R31: 46113 | T31: 20 | U31: 46143 | W31: 20 | X31: 46143 | Z31: 9 | AA31: 46143 | AC31: 200 | AD31: 46146
H32: 10 | I32: 46187 | K32: 5 | L32: 46105 | N32: 50 | O32: 46142 | Q32: 27 | R32: 46143 | T32: 50 | U32: 46147 | W32: 50 | X32: 46147 | Z32: 154 | AA32: 46194
H33: 10 | I33: 46202 | K33: 1 | L33: 46106 | N33: 11 | O33: 46149 | Q33: 50 | R33: 46147 | W33: -2 | Z33: 100 | AA33: 46302
K34: 10 | L34: 46271 | N34: 30 | O34: 46194 | Z34: 120
K35: 20 | L35: 46179
K36: 50 | L36: 46190
K37: -5 | L37: 46194
K38: 4 | L38: 46029
K39: 20 | L39: 46214
K40: 2 | L40: 46216
K41: 10 | L41: 46217
K42: 10 | L42: 46230
B54: =SUM(B31:B53) -> 0 | E54: =SUM(E31:E53) -> 3 | H54: =SUM(H31:H53) -> 21 | K54: =SUM(K31:K53) -> 133 | N54: =SUM(N31:N53) -> 101 | Q54: =SUM(Q31:Q53) -> 83 | T54: =SUM(T31:T53) -> 70 | W54: =SUM(W31:W53) -> 68 | Z54: =SUM(Z31:Z53) -> 383 | AC54: =SUM(AC31:AC53) -> 200
B57: Coster | E57: Stand Mobile | K57: استيكر خماسين | N57: ميدالية ميلاد | Q57: ستاند ميلاد | T57: شجرة | W57: بازل ميلاد | Z57: رحلات بولس خشب | AC57: رحلات بولس ورق
B58: عدد | C58: تاريخ | E58: عدد | F58: تاريخ | H58: عدد | I58: تاريخ | K58: عدد | L58: تاريخ | N58: عدد | O58: تاريخ | Q58: عدد | R58: تاريخ | T58: عدد | U58: تاريخ | W58: عدد | X58: تاريخ | Z58: عدد | AA58: تاريخ | AC58: عدد | AD58: تاريخ
B59: 10 | C59: 46234 | K59: 9 | L59: 46146 | N59: 8 | O59: 46146 | Q59: 5 | R59: 46146 | T59: 11 | U59: 46146 | W59: 7 | X59: 46146 | Z59: 18 | AA59: 46149 | AC59: 10 | AD59: 46155
Z60: 5 | AA60: 46152 | AC60: 16
Z61: 6 | AA61: 46156 | AC61: 5 | AD61: 46029
Z62: 10 | AA62: 46181 | AC62: 11 | AD62: 46209
Z63: 20 | AA63: 46189 | AC63: 11 | AD63: 46216
...

Sheet حسابات شهرية
A4: الشهر | B4: المبيعات | C4: الخصومات | D4: تكلفة المنتجات | E4: المصاريف الإدارية | F4: صافي الربح | H4: الشهر | I4: براند الورش | J4: الورشة | K4: إدارية عامة | L4: براند مارينا | M4: الإجمالي
A5: 2026-03 | B5: 46688 | C5: 150 | D5: 20980 | E5: 3780 | F5: 21928 | H5: 46082 | I5: 22680 | J5: 1650 | K5: 3780 | L5: 0 | M5: 28110
A6: 2026-04 | B6: 52640 | C6: 1545 | D6: 25265 | E6: -395 | F6: 27770 | H6: 46113 | I6: 20435 | J6: 750 | K6: -395 | L6: 0 | M6: 20790
A7: 2026-05 | B7: 21002 | C7: 725 | D7: 11042 | E7: 8350 | F7: 1610 | H7: 46143 | I7: 10900 | J7: 750 | K7: 1050 | L7: 5350 | M7: 18050
A8: 2026-06 | B8: 66671 | C8: 920 | D8: 38370 | E8: 6191 | F8: 22110 | H8: 46174 | I8: 42074 | J8: 5235 | K8: 3735 | L8: 0 | M8: 51044
A9: بدون تاريخ | B9: 400 | C9: 0 | D9: 270 | E9: 21316 | F9: -21186 | H9: بدون تاريخ | I9: 0 | J9: 0 | K9: 0 | L9: 0 | M9: 0
A10: الإجمالي العام | B10: =SUM(جدول_2[المبيعات]) -> 187401 | C10: =SUM(جدول_2[الخصومات]) -> 3340 | D10: =SUM(جدول_2[تكلفة المنتجات]) -> 95927 | E10: =SUM(جدول_2[المصاريف الإدارية]) -> 39242 | F10: =SUM(جدول_2[صافي الربح]) -> 52232 | H10: الإجمالي العام | I10: =SUM(جدول_3[براند الورش]) -> 96089 | J10: =SUM(جدول_3[الورشة]) -> 8385 | K10: =SUM(جدول_3[إدارية عامة]) -> 8170 | L10: =SUM(جدول_3[براند مارينا]) -> 5350 | M10: =SUM(جدول_3[الإجمالي]) -> 117994
A15: الشهر | B15: المبيعات | C15: براند الورش | D15: إدارية عامة | E15: صافي الربح | F15: حساب الورشة | G15: صافي الربح بدون مصاريف الورشة
A16: 46082 | B16: 46688 | C16: 22680 | D16: 1000 | E16: =B16-C16-D16 -> 23008 | F16: 225 | G16: =E16+F16 -> 23233
A17: 46113 | B17: 52640 | C17: 20435 | D17: 2150 | E17: =B17-C17-D17 -> 30055 | F17: 750 | G17: =E17+F17 -> 30805
A18: 46143 | B18: 21002 | C18: 10900 | D18: 1050 | E18: =B18-C18-D18 -> 9052 | F18: 750 | G18: =E18+F18 -> 9802
A19: 46174 | B19: 66671 | C19: 42074 | D19: 3735 | E19: =B19-C19-D19 -> 20862 | F19: 5235 | G19: =E19+F19 -> 26097
B24: الشهر | C24: المبيعات | D24: الخصومات | E24: تكلفة المنتجات | F24: إدارية عامة | G24: براند النوتات | H24: صافي الربح بدون مصاريف الورشة | I24: حساب الورشة (كبارواطفال) | J24: صافي الربح
B25: 46082 | C25: 46688 | D25: 150 | E25: 20980 | F25: 1000 | G25: 0 | H25: =C25-D25-E25-F25-G25 -> 24558 | I25: 225 | J25: =H25-I25 -> 24333
B26: 46113 | C26: 52640 | D26: 1545 | E26: 25265 | F26: 2150 | G26: 0 | H26: =C26-D26-E26-F26-G26 -> 23680 | I26: 750 | J26: =H26-I26 -> 22930
B27: 46143 | C27: 21002 | D27: 725 | E27: 11042 | F27: 1050 | G27: 5350 | H27: =C27-D27-E27-F27-G27 -> 2835 | I27: 750 | J27: =H27-I27 -> 2085
B28: 46174 | C28: 66671 | D28: 920 | E28: 38370 | F28: 3735 | G28: 0 | H28: =C28-D28-E28-F28-G28 -> 23646 | I28: 5235 | J28: =H28-I28 -> 18411
B29: 46204 | H29: =C29-D29-E29-F29-G29 -> 0 | J29: =H29-I29 -> 0
B30: 46235 | H30: =C30-D30-E30-F30-G30 -> 0 | J30: =H30-I30 -> 0
B31: 46266 | H31: =C31-D31-E31-F31-G31 -> 0 | J31: =H31-I31 -> 0
B32: 46296 | H32: =C32-D32-E32-F32-G32 -> 0 | J32: =H32-I32 -> 0
B33: 46327 | H33: =C33-D33-E33-F33-G33 -> 0 | J33: =H33-I33 -> 0
B34: 46357 | H34: =C34-D34-E34-F34-G34 -> 0 | J34: =H34-I34 -> 0
B38: معادلة تقسيم الارباح
C39: الارباح | D39: الكنيسة | G39: تطوير | H39: 1 | I39: 2 | J39: 3 | K39: 4
C40: 1 | D40: 0.5 | E40: حساب الورشة | F40: باقي للكنيسة | G40: 0 | H40: 0.14 | I40: 0.14 | J40: 0.14 | K40: 0.08
B41: 46082 | C41: =H25 -> 24558 | D41: =$C$41*$D$40/$C$40 -> 12279 | E41: 1650 | F41: =D41-E41 -> 10629 | G41: =C41*$G$40/$C$40 -> 0 | H41: 2455.8 | I41: 2455.8 | J41: 2455.8 | K41: 1227.9
B42: 46113 | C42: =H26 -> 23680 | D42: =$C$42*$D$40/$C$40 -> 11840 | E42: 750 | F42: =D42-E42 -> 11090 | G42: =C42*$G$40/$C$40 -> 0 | H42: 2368 | I42: 2368 | J42: 2368 | K42: 1184
B43: 46143 | C43: =H27 -> 2835 | D43: =$C$43*$D$40/$C$40 -> 1417.5 | E43: 750 | F43: =D43-E43 -> 667.5 | G43: =C43*$G$40/$C$40 -> 0 | H43: 283.5 | I43: 283.5 | J43: 283.5 | K43: 141.75
B44: 46174 | C44: =H28 -> 23646 | D44: =$C$44*$D$40/$C$40 -> 11823 | E44: 5235 | F44: =D44-E44 -> 6588 | G44: =C44*$G$40/$C$40 -> 0 | H44: 2364.6 | I44: 2364.6 | J44: 2364.6 | K44: 1182.3
B45: 46204 | D45: =C45*$D$40/$C$40 -> 0 | F45: =D45-E45 -> 0 | G45: =C45*$G$40/$C$40 -> 0 | H45: =$C$45*H40/$C$40 -> 0 | I45: =C45*$I$40/$C$40 -> 0 | J45: =C45*$J$40/$C$40 -> 0 | K45: =C45*$K$40/$C$40 -> 0
B46: 46235 | D46: =C46*$D$40/$C$40 -> 0 | F46: =D46-E46 -> 0 | G46: =C46*$G$40/$C$40 -> 0 | H46: =C46*$H$40/$C$40 -> 0 | I46: =C46*$I$40/$C$40 -> 0 | J46: =C46*$J$40/$C$40 -> 0 | K46: =C46*$K$40/$C$40 -> 0
B47: 46266 | D47: =C47*$D$40/$C$40 -> 0 | F47: =D47-E47 -> 0 | G47: =C47*$G$40/$C$40 -> 0 | H47: =C47*$H$40/$C$40 -> 0 | I47: =C47*$I$40/$C$40 -> 0 | J47: =C47*$J$40/$C$40 -> 0 | K47: =C47*$K$40/$C$40 -> 0
B48: 46296 | D48: =C48*$D$40/$C$40 -> 0 | F48: =D48-E48 -> 0 | G48: =C48*$G$40/$C$40 -> 0 | H48: =C48*$H$40/$C$40 -> 0 | I48: =C48*$I$40/$C$40 -> 0 | J48: =C48*$J$40/$C$40 -> 0 | K48: =C48*$K$40/$C$40 -> 0
B49: 46327 | D49: =C49*$D$40/$C$40 -> 0 | F49: =D49-E49 -> 0 | G49: =C49*$G$40/$C$40 -> 0 | H49: =C49*$H$40/$C$40 -> 0 | I49: =C49*$I$40/$C$40 -> 0 | J49: =C49*$J$40/$C$40 -> 0 | K49: =C49*$K$40/$C$40 -> 0
B50: 46357 | D50: =C50*$D$40/$C$40 -> 0 | F50: =D50-E50 -> 0 | G50: =C50*$G$40/$C$40 -> 0 | H50: =C50*$H$40/$C$40 -> 0 | I50: =C50*$I$40/$C$40 -> 0 | J50: =C50*$J$40/$C$40 -> 0 | K50: =C50*$K$40/$C$40 -> 0
C51: =SUM(C41:C50) -> 74719 | D51: =SUM(D41:D50) -> 37359.5 | E51: =SUM(E41:E50) -> 8385 | F51: =SUM(F41:F50) -> 28974.5 | G51: =SUM(G41:G50) -> 0 | H51: =SUM(H41:H50) -> 7471.9 | I51: =SUM(I41:I50) -> 7471.9 | J51: =SUM(J41:J50) -> 7471.9 | K51: =SUM(K41:K50) -> 3735.95
G54: 46082
G55: 46113 | H55: 2000 | I55: 2000 | J55: 2000 | K55: 500
G56: 46143
...

Sheet تحليل بيانات مارس-يوليو
A17: Order Details | B17: Total_Revenue | F17: المنطقة_cleaned | G17: Total_Revenue | K17: المحافطة_cleaned | L17: Total_Revenue | Q17: المنتج | R17: المبيعات | W17: المحافظة | X17: عدد الطلبات | Y17: إجمالي المبيعات
A18: رحلات بولس خشب | B18: 46450 | K18: القاهرة | L18: 87954 | Q18: رحلات بولس خشب | R18: 46450 | W18: شبرا | X18: 61 | Y18: 19761
A19: القيامة شباب | B19: 37970 | F19: شبرا | G19: 19761 | K19: الجيزة | L19: 25286 | Q19: القيامة شباب | R19: 37970 | W19: اسكندرية | X19: 45 | Y19: 17362
A20: أسبوع الالام | B20: 37520 | F20: مدينة نصر | G20: 6580 | K20: المنيا | L20: 20150 | Q20: أسبوع الالام | R20: 37520 | W20: المنيا | X20: 41 | Y20: 16440
A21: أسفار الكتاب المقدس | B21: 16050 | F21: الضاهر | G21: 6232 | K21: الإسكندرية | L21: 17762 | Q21: أسفار الكتاب المقدس | R21: 16050 | W21: أخرى | X21: 26 | Y21: 10072
A22: رحلات بولس ورق | B22: 11100 | F22: مصر الجديدة | G22: 5790 | K22: القليوبية | L22: 14660 | Q22: رحلات بولس ورق | R22: 10700 | W22: اسيوط | X22: 20 | Y22: 9630
A23: القيامة ابتدائي | B23: 9900 | F23: العبور | G23: 5130 | K23: غير محدد | L23: 12172 | Q23: القيامة ابتدائي | R23: 9900 | W23: الاقصر | X23: 16 | Y23: 8100
A24: خيمة الاجتماع | B24: 9240 | F24: حلوان | G24: 4150 | K24: اسيوط | L24: 9630 | Q24: خيمة الاجتماع | R24: 9240 | W24: مدينة نصر | X24: 15 | Y24: 6580
A25: Bible Note | B25: 7740 | F25: رمسيس | G25: 3250 | K25: الاقصر | L25: 8100 | Q25: Bible Note | R25: 7740 | W25: الضاهر | X25: 25 | Y25: 6232
A26: اختام الرؤيا | B26: 7680 | F26: حدايق الاهرام | G26: 3245 | K26: اسوان | L26: 5655 | Q26: اختام الرؤيا | R26: 7680 | W26: مصر الجديدة | X26: 11 | Y26: 5790
A27: أحاد الخماسين | B27: 7375 | F27: التجمع | G27: 3190 | K27: البحر الاحمر | L27: 5080 | Q27: أحاد الخماسين | R27: 7375 | W27: اسوان | X27: 15 | Y27: 5655
Q28: القيامة فردية 300جرام | R28: 6775 | W28: العبور | X28: 8 | Y28: 5130
Q29: أحاد الصوم | R29: 4570 | W29: الجيزة | X29: 10 | Y29: 5050
Q30: كارت حضور | R30: 4320 | W30: السويس | X30: 18 | Y30: 4470
Q31: الروح القدس | R31: 3840 | W31: حلوان | X31: 10 | Y31: 4150
Q32: قضاه | R32: 3680 | W32: بورسعيد | X32: 6 | Y32: 3300
A33: أود أن أعتذر منك، حيث لا يمكنني إكمال طلبك بالكامل الآن بسبب الوصول إلى الحد الأقصى من القدرة على المعالجة خلال هذه الجولة الواحدة. ما تم إنجازه حتى الآن: • فحص وتحليل البيانات: قمت بمراجعة الجداول المتاحة (جدول الطلبات Orders، جدول تحليل البيانات، لوحة التحكم المالية، ولوحة تحكم CRM). • تنظيف البيانات وحساب الإجماليات: قمت بتصفية الطلبات الصحيحة وحساب الإجماليات العامة بدقة، حيث تبين أن: • إجمالي المبيعات: 246,907 جنيه. • إجمالي عدد القطع (الكمية): 5,835 قطعة. • إجمالي عدد المعاملات/الطلبات: 720 معاملة. • عدد العملاء الفريدين: 371 عميلاً. • عدد الكنائس/الجهات الدينية: تم تحديد حوالي 18 عميلاً فريداً يمثلون كنائس أو اجتماعات (بإجمالي 28 طلباً). • عدد المحافظات: تم تحديد 24 محافظة فريدة بعد تنظيف المسميات (بالإضافة إلى طلبات غير محددة أو خارج مصر). • تحديد القوائم الأعلى (Top 10): قمت بإجراء الحسابات اللازمة لاستخراج أعلى 10 محافظات، وأعلى 10 عملاء، وأعلى 10 منتجات من حيث المبيعات والقطع والطلبات. العمل المتبقي: • تنسيق وعرض القوائم المفصلة لأعلى 10 عناصر في كل تصنيف (المحافظات، العملاء، والمنتجات) بشكل منظم ومكتوب بالكامل في ردك لتتمكن من قراءتها ومقارنتها بسهولة. | Q33: الخروج | R33: 3600 | W33: رمسيس | X33: 17 | Y33: 3250
Q34: خريطة اورشليم | R34: 2720 | W34: حدايق الاهرام | X34: 13 | Y34: 3245
Q35: باكيدچ | R35: 2000 | W35: التجمع | X35: 11 | Y35: 3190
Q36: الخليقة ابتدائي | R36: 1601 | W36: سوهاج | X36: 16 | Y36: 3110
Q37: اعمال الرسل | R37: 1560 | W37: جسر السويس | X37: 7 | Y37: 3050
Q38: ملوك | R38: 1200 | W38: الكوربة | X38: 2 | Y38: 2430
Q39: ختم حضور | R39: 1100 | W39: النزهة | X39: 3 | Y39: 2420
Q40: خريطة البشارة | R40: 1040 | W40: الرحاب | X40: 14 | Y40: 2350
Q41: File | R41: 1000 | W41: الشيخ زايد | X41: 2 | Y41: 2340
Q42: خيمة الاجتماع فردي | R42: 825 | W42: بني سويف | X42: 10 | Y42: 2300
Q43: ابطال ١ | R43: 480 | W43: ٦ اكتوبر | X43: 7 | Y43: 2160
Q44: Todo List | R44: 391 | W44: المعادي | X44: 6 | Y44: 2080
Q45: Tracker Note | R45: 330 | W45: مصر القديمة | X45: 4 | Y45: 2020
... Q50: عمل الفلك | R50: 11 | W50: الخصوص | X50: 5 | Y50: 1940
W51: البحر الاحمر | X51: 9 | Y51: 1920
W52: المطرية | X52: 15 | Y52: 1920
W53: القاهرة | X53: 2 | Y53: 1720
W54: دمنهور | X54: 4 | Y54: 1660
W55: الهرم | X55: 5 | Y55: 1650
W56: شبرا الخيمة | X56: 8 | Y56: 1640
W57: جيزة | X57: 10 | Y57: 1635
W58: كنيستنا | X58: 7 | Y58: 1480
W59: الزيتون | X59: 4 | Y59: 1480
W60: امبابة | X60: 8 | Y60: 1470
...

Sheet Private
B3: Deposit | E3: Payed | G3: Total | I3: عند مارينا | K3: Kerolos | N3: Abona Daniel
B4: =SUMIF(Orders!$M$2:$M$1682,"Instapay",Orders!$L$2:$L$1682) -> 129035 | C4: instapay | E4: =SUMIF(Orders!$R$2:$R$1682,"Instapay",Orders!$Q$2:$Q$1682) -> 9980 | F4: instapay | G4: =B4+E4 -> 139015 | I4: =G4-K4 -> 14460 | K4: ='محفظتي'!A358 -> 124555 | L4: instapay | N4: 30000 | O4: 0.40069444 | P4: 46132
B5: =SUMIF(Orders!$M$2:$M$1682,"VF",Orders!$L$2:$L$1682) -> 11195 | C5: VF | E5: =SUMIF(Orders!$R$2:$R$1682,"VF",Orders!$Q$2:$Q$1682) -> 0 | F5: VF | G5: =B5+E5 -> 11195 | I5: =G5-K5 -> -2175 | K5: ='محفظتي'!E358 -> 13370 | L5: VF | N5: 3000 | O5: 0.34861111 | P5: 46212
B6: =SUMIF(Orders!$M$2:$M$1682,"CASH",Orders!$L$2:$L$1682) -> 2881 | C6: Cash | E6: =SUMIF(Orders!$R$2:$R$1682,"CASH",Orders!$Q$2:$Q$1682) -> 5345 | F6: Cash | G6: =B6+E6 -> 8226 | I6: =G6-K6 -> -4484 | K6: ='محفظتي'!I358 -> 12710 | L6: Cash | N6: 3000 | O6: KKKK | P6: 46212
B7: =SUMIF(Orders!$M$2:$M$1682,"Visa post ",Orders!$L$2:$L$1682) -> 0 | C7: Visa post | E7: =SUMIF(Orders!$R$2:$R$1682,"Visa post ",Orders!$Q$2:$Q$1682) -> 7265 | F7: Visa post | G7: =B7+E7 -> 7265 | I7: =G7-K7 -> 1665 | K7: ='محفظتي'!M358 -> 5600 | L7: Visa post
B8: =SUMIF(Orders!$M$2:$M$1682,"Postaa",Orders!$L$2:$L$1682) -> 0 | C8: Postaa | E8: =SUMIF(Orders!$R$2:$R$1682,"Postaa",Orders!$Q$2:$Q$1682) -> 21952 | F8: Postaa | G8: =B8+E8 -> 21952 | I8: =G8-K8 -> 1552 | K8: ='محفظتي'!Q358 -> 20400 | L8: Postaa
B9: =SUMIF(Orders!$M$2:$M$1682,"Last",Orders!$L$2:$L$1682) -> 0 | C9: Last | E9: =SUMIF(Orders!$R$2:$R$1682,"Last",Orders!$Q$2:$Q$1682) -> 24473 | F9: Last | G9: =B9+E9 -> 24473 | I9: =G9-K9 -> -8757 | K9: ='محفظتي'!U358 -> 33230 | L9: Last
B10: =SUM(B4:B8) -> 143111 | E10: =SUM(E4:E9) -> 69015 | G10: =B10+E10 -> 212126 | I10: =SUM(I4:I9) -> 2261 | K10: =SUM(K4:K9) -> 209865 | N10: =SUM(N4:N9) -> 36000
C17: Total | D17: Deposit | E17: Payed | F17: Marina | G17: remaining | H17: Kerolos | I17: George | J17: Warsha | K17: Expenses | L17: Note | M17: Abona | N17: Box Warsha
C18: =SUM(Table1[Total]) -> 250102 | D18: =SUM(Orders!L2:L1682) -> 144051 | E18: =SUM(Orders!Q2:Q1682) -> 69015 | F18: =D18+E18 -> 213066 | G18: =C18-D18-E18 -> 37036 | H18: =K10 -> 209865 | I18: ='محفظتي'!Y358 -> 131683.6 | J18: ='محفظتي'!AC358 -> 10508 | K18: ='محفظتي'!AG358 -> 27335 | L18: ='محفظتي'!AK358 -> 5350 | M18: =N10 -> 36000 | N18: =H18-I18-J18-K18-M18-L18 -> -1011.6
H19: =F18-H18 -> 3201
K21: =C18-I18-K18 -> 91083.4 | M21: =M18+N18 -> 34988.4
K22: =K21-J18 -> 80575.4
C23: =SUM(Orders!S3:S1683) -> 35798

Sheet محفظتي
A1: Instapay | E1: VF | I1: Cash | M1: Visa post | Q1: Postaa | U1: Last | Y1: حساب جورج
A2: 1230 | B2: 0.96736111 | C2: 46099 | E2: 240 | F2: 0.40555556 | G2: 46100 | I2: 680 | J2: روف الكنيسة | K2: 46103 | M2: 5250 | N2: سحب | O2: 46121 | Q2: 13400 | R2: كاش | S2: 46140 | U2: 8240 | V2: VF | W2: 46200 | Y2: حساب براند الورش | AC2: حساب الورشة | AG2: مصاريف إدارية | AL2: براند مارينا
A3: 1120 | B3: 0.66805556 | C3: 46099 | E3: 500 | F3: 0.46736111 | G3: 46100 | I3: 1950 | J3: ميرا | K3: 46108 | M3: 350 | N3: سحب | O3: 46156 | Q3: 2000 | R3: سحب | S3: 46156 | U3: 6270 | V3: Instapay | W3: 46208 | Y3: 650 | Z3: اسفار | AA3: 46102 | AC3: 225 | AD3: فلير اسبوع الالام | AE3: 46101 | AG3: 30 | AH3: توكتوك | AI3: 46103 | AK3: 600 | AL3: Bible Note | AM3: 46143
A4: 120 | B4: 0.78402778 | C4: 46099 | E4: 100 | F4: 0.69652778 | G4: 46100 | I4: 1000 | J4: شحن | K4: 46119 | Q4: 5000 | R4: سحب | S4: 46183 | U4: 18720 | V4: Dalilah | W4: 46230 | Y4: 960 | Z4: 6+6+6+20+10 | AA4: 46102 | AC4: 275 | AD4: ورشة الملوك | AE4: 46101 | AG4: 2800 | AH4: بريد | AI4: 46105 | AK4: 600 | AL4: Tracker | AM4: 46143
A5: 400 | B5: 0.84097222 | C5: 46099 | E5: 500 | F5: 0.60277778 | G5: 46101 | I5: 400 | J5: ليليان | K5: 46119 | Y5: 960 | Z5: تغليف | AA5: 46102 | AC5: 60 | AD5: فلير خيمة الاجتماع | AE5: 46102 | AG5: 950 | AH5: بريد | AI5: 46112 | AK5: 800 | AL5: Basic Note | AM5: 46143
A6: 120 | B6: 0.045833333 | C6: 46100 | E6: 250 | F6: 0.91736111 | G6: 46101 | I6: 585 | J6: باقي حساب | K6: 46130 | Y6: 820 | Z6: استيكر | AA6: 46102 | AC6: 450 | AD6: فلير العهد القديم | AE6: 46102 | AG6: 300 | AH6: فليرات | AI6: 46113 | AK6: 500 | AL6: Todo List | AM6: 46143
A7: 160 | B7: 0.40902778 | C7: 46100 | E7: 120 | F7: 0.65277778 | G7: 46102 | I7: 1000 | J7: براند نوت | K7: 46144 | O7: =IF(M7<>"",TODAY(),"") | S7: =IF(Q7<>"",TODAY(),"") | W7: =IF(U7<>"",TODAY(),"") | Y7: 600 | Z7: أظرف | AA7: 46104 | AC7: 640 | AD7: 8 ورش لميرنا | AE7: 46103 | AG7: 155 | AH7: باركود شحن | AI7: 46113 | AK7: 1100 | AL7: Bible Note | AM7: 46143
A8: 80 | B8: 0.69375 | C8: 46100 | E8: 160 | F8: 0.71041667 | G8: 46103 | I8: 200 | J8: نت لمريم | K8: 46152 | O8: =IF(M8<>"",TODAY(),"") | S8: =IF(Q8<>"",TODAY(),"") | W8: =IF(U8<>"",TODAY(),"") | Y8: 9700 | Z8: 300+21 | AA8: 46104 | AC8: 750 | AD8: مجات | AE8: 46116 | AG8: 50 | AH8: سلوتب | AI8: 46113 | AK8: 1750 | AL8: شنط | AM8: 46149
A9: 500 | B9: 0.84305556 | C9: 46100 | E9: 400 | F9: 0.051388889 | G9: 46104 | I9: 20 | J9: باقي حساب سالي | K9: 46166 | O9: =IF(M9<>"",TODAY(),"") | S9: =IF(Q9<>"",TODAY(),"") | W9: =IF(U9<>"",TODAY(),"") | Y9: 820 | Z9: تقطيع استيكر | AA9: 46104 | AC9: 750 | AD9: اقلام | AE9: 46156 | AG9: 150 | AH9: موصلات | AI9: 46113
A10: 240 | B10: 0.62916667 | C10: 46101 | E10: 600 | F10: 0.94375 | G10: 46105 | I10: 940 | J10: Xpress | K10: 46179 | O10: =IF(M10<>"",TODAY(),"") | S10: =IF(Q10<>"",TODAY(),"") | W10: =IF(U10<>"",TODAY(),"") | Y10: 280 | Z10: 14 ربع استيكر | AA10: 46105 | AC10: 380 | AD10: كوبيات 380 | AE10: 46184 | AG10: 640 | AH10: فليرات | AI10: 46119
A11: 120 | B11: 0.79930556 | C11: 46101 | E11: 250 | F11: 0.99444444 | G11: 46109 | I11: 1000 | J11: مصاريف | K11: 46221 | Y11: 340 | Z11: 17 ورشة | AA11: 46105 | AC11: 450 | AD11: ستان ولزق 450 | AE11: 46184 | AG11: 355 | AH11: اكواد | AI11: 46119
A12: 280 | B12: 0.87638889 | C12: 46101 | E12: 320 | F12: 0.66527778 | G12: 46113 | I12: 4935 | J12: دليله | K12: 46231 | Y12: 150 | Z12: 10 اظرف | AA12: 46105 | AC12: 135 | AD12: مناديل 135 | AE12: 46184 | AG12: 300 | AH12: مواصلات | AI12: 46119
A13: 280 | B13: 0.87777778 | C13: 46101 | E13: 160 | F13: 0.97916667 | G13: 46113 | Y13: 540 | Z13: 27 ربع | AA13: 46105 | AC13: 30 | AD13: لزق تي ب 30 | AE13: 46184 | AG13: 200 | AH13: شحن نت | AI13: 46119
A14: 160 | B14: 0.87847222 | C14: 46101 | E14: 215 | F14: 0.72916667 | G14: 46114 | Y14: 280 | Z14: 14 استيكر | AA14: 46105 | AC14: 110 | AD14: معطر وكيس زباله 109 | AE14: 46184 | AG14: -3750 | AH14: بريد | AI14: 46121
A15: 200 | B15: 0.88402778 | C15: 46101 | E15: 250 | F15: 0.74722222 | G15: 46114 | Y15: 300 | Z15: 20 ظرف | AA15: 46106 | AC15: 200 | AD15: بابلز 200 | AE15: 46184 | AG15: 355 | AH15: اكواد | AI15: 46130
A16: 240 | B16: 0.93680556 | C16: 46101 | E16: 160 | F16: 0.91527778 | G16: 46114 | Y16: 1020 | Z16: 51 ربع | AA16: 46106 | AC16: 90 | AD16: لازق نقاشه 90 | AE16: 46193 | AG16: 70 | AH16: توكتوك | AI16: 46130
A17: 300 | B17: 0.96944444 | C17: 46101 | E17: 120 | F17: 0.95902778 | G17: 46114 | Y17: 520 | Z17: 26 استيكر | AA17: 46106 | AC17: 150 | AD17: طابا 150 | AE17: 46193 | AG17: 120 | AH17: اوردر رجع | AI17: 46130
A18: 80 | B18: 0.97361111 | C18: 46101 | E18: 160 | F18: 0.96944444 | G18: 46114 | Y18: 360 | Z18: 18ربع | AA18: 46107 | AC18: 200 | AD18: وصله 200 | AE18: 46193 | AG18: 150 | AH18: شحن | AI18: 46130
A19: 160 | B19: 0.98263889 | C19: 46101 | E19: 150 | F19: 0.54930556 | G19: 46115 | Y19: 40 | Z19: 2ربع استيكر | AA19: 46107 | AC19: 710 | AD19: هدايا 710 | AE19: 46193 | AG19: 50 | AH19: شحن | AI19: 46130
A20: 120 | B20: 0.080555556 | C20: 46102 | E20: 160 | F20: 0.77638889 | G20: 46116 | Y20: 400 | Z20: 20ربع | AA20: 46109 | AC20: 50 | AD20: توكتوك 50 | AE20: 46193 | AG20: 200 | AH20: توكتوك | AI20: 46130
A21: 240 | B21: 0.56597222 | C21: 46102 | E21: 1000 | F21: 0.69722222 | G21: 46126 | Y21: 100 | Z21: 5اربع | AA21: 46109 | AC21: 230 | AD21: ورشة ابراهيم | AE21: 46201 | AG21: 160 | AH21: باقي اوردر | AI21: 46130
A22: 400 | B22: 0.57777778 | C22: 46102 | E22: 160 | F22: 0.69861111 | G22: 46126 | Y22: 75 | Z22: 5 اظرف | AA22: 46109 | AC22: 230 | AD22: ورشة خيمة الاجتماع a5 | AE22: 46201 | AG22: 650 | AH22: فليرات | AI22: 46144
A23: 80 | B23: 0.61458333 | C23: 46102 | E23: 240 | F23: 0.69861111 | G23: 46126 | Y23: 80 | Z23: 4ربع استيكر | AA23: 46110 | AC23: 100 | AD23: لوجو الحكاية ابتدائي | AE23: 46201 | AG23: 100 | AH23: مرتجع | AI23: 46142
A24: 200 | B24: 0.62986111 | C24: 46102 | E24: 255 | F24: 0.7 | G24: 46126 | Y24: 1000 | Z24: 50ربع القيامة | AA24: 46111 | AC24: 275 | AD24: بداية الخدمة | AE24: 46201 | AG24: 200 | AH24: توكتوك | AI24: 46144
... A37: 200 | B37: 0.6875 | C37: 46103 | E37: 700 | F37: 0.67708333 | G37: 46203 | Y37: 850 | Z37: 34 استيكر | AA37: 46116 | AC37: 60 | AD37: ورش خيمه الاجتماع تغليف بلاستك | AE37: 46205 | AG37: 250 | AH37: بلالين | AI37: 46213
A38: 160 | B38: 0.70555556 | C38: 46103 | E38: 1475 | G38: 46215 | Y38: 760 | Z38: 38ربع | AA38: 46116 | AC38: 75 | AD38: استيكر ورشه خيمه الاجتماع | AE38: 46205 | AG38: 400 | AH38: ج بسكويت | AI38: 46213
A39: 320 | B39: 0.70694444 | C39: 46103 | Y39: 300 | Z39: 10 استيكر | AA39: 46116 | AC39: 90 | AD39: لوج الورشه | AE39: 46205 | AG39: 350 | AH39: قلب كلون | AI39: 46213
A40: 480 | B40: 0.81875 | C40: 46103 | Y40: 2000 | Z40: 100ربع | AA40: 46118 | AC40: 300 | AD40: طباعه الرحله التبشيرية A4 | AE40: 46205 | AG40: 80 | AH40: توكتوك | AI40: 46213
A41: 320 | B41: 0.98194444 | C41: 46103 | Y41: 850 | Z41: 34 استيكر | AA41: 46118 | AC41: 75 | AD41: فلاير خيمه الاجتماع | AE41: 46205 | AG41: 240 | AH41: لزق نقاشة | AI41: 46213
A42: 40 | B42: 0.98611111 | C42: 46103 | Y42: 1000 | Z42: 50ربع | AA42: 46119 | AC42: 150 | AD42: طباعه رحله التبشيرية الاولى و التانية A5 | AE42: 46205 | AG42: 600 | AH42: عصير لابتدائي | AI42: 46204
A43: 160 | B43: 0.98819444 | C43: 46103 | Y43: 450 | Z43: 18ربع | AA43: 46119 | AC43: 220 | AD43: باسبور | AE43: 46205 | AG43: 220 | AH43: عصام | AI43: 46207
A44: 400 | B44: 0.045138889 | C44: 46104 | Y44: 1000 | Z44: 50ربع | AA44: 46120 | AC44: 320 | AD44: باسبور | AE44: 46207 | AG44: 200 | AH44: نسكافيه | AI44: 46207
A45: 160 | B45: 0.54861111 | C45: 46104 | Y45: 450 | Z45: 18ربع | AA45: 46120 | AC45: 25 | AD45: ربع فرخ استيكر + تشريح | AE45: 46207 | AG45: 250 | AH45: لاصق | AI45: 46206
A46: 80 | B46: 0.63958333 | C46: 46104 | Y46: 385 | Z46: 50 ورشة فر | AA46: 46121 | AC46: 400 | AD46: تين+توكتوك | AE46: 46228 | AG46: 6720 | AH46: دليلة | AI46: 46230
A47: 80 | B47: 0.64097222 | C47: 46104 | Y47: 800 | Z47: باقي الورش | AA47: 46126 | AC47: 18 | AD47: طباعة ورق عادى | AE47: 46228 | AG47: 140 | AH47: مقصات | AI47: 46218
A48: 160 | B48: 0.64236111 | C48: 46104 | Y48: 850 | Z48: 30ورشة | AA48: 46126 | AC48: 150 | AD48: كروت كيرلس ابراهيم | AE48: 46228 | AG48: 4935 | AH48: دليله | AI48: 46231
A49: 280 | B49: 0.64583333 | C49: 46104 | Y49: 460 | Z49: 23ربع | AA49: 46127 | AC49: 100 | AD49: ربع فرخ كوشية | AE49: 46228
A50: 160 | B50: 0.80138889 | C50: 46104 | Y50: 200 | Z50: 8 استيكر | AA50: 46127
A51: 240 | B51: 0.80347222 | C51: 46104 | Y51: 400 | Z51: ٢٠ ربع | AA51: 46130
A52: 80 | B52: 0.80694444 | C52: 46104 | Y52: 200 | Z52: ٨ استيكر | AA52: 46130
...

Sheet CRM Dashboard
A2: نظام إدارة علاقات العملاء (CRM Dashboard)
A4: إجمالي العملاء | B4: إجمالي الطلبات | C4: إجمالي المبيعات | D4: المستحقات المتبقية
A5: =IFERROR(__xludf.DUMMYFUNCTION("COUNTUNIQUE(Clients!A2:A1000)"),1.0) -> 1 | B5: =COUNTA(#REF!) -> 1 | C5: {=SUM(IFERROR(Orders!K2:K1000, 0))} -> 250102 | D5: {=SUM(IFERROR(Orders!S2:S1000, 0))} -> 35798
A7: مبيعات الورشة (Workshop) | B7: مبيعات البراند (Brand) | C7: المبيعات الرقمية (Digital)
A8: {=SUM(SUMIF(TRIM(Orders!G2:G1000), TRIM(#REF!), Orders!K2:K1000))} -> 0 | B8: {=SUM(SUMIF(TRIM(Orders!G2:G1000), TRIM(#REF!), Orders!K2:K1000))} -> 0 | C8: =SUM(Orders!K2:K1000) - A8 - B8 -> 250102
A11: البحث عن العميل (Customer Search & Card)
A12: اسم العميل: | B12: الفريد كمال
A13: كود العميل (ClientID) | B13: رقم الهاتف (Phone) | C13: العنوان (Address) | D13: عدد الطلبات (Total Orders) | E13: إجمالي المبيعات (Total Spend) | F13: المستحقات المتبقية (Balance Rest)
A14: =IF(B12="", "", B12) -> الفريد كمال | B14: {=IF(B12="", "", XLOOKUP(B12, Clients!A3:A1000, Clients!B3:B1000, "غير موجود"))} | C14: {=IF(B12="", "", XLOOKUP(B12, Clients!A3:A1000, Clients!C3:C1000, "غير موجود"))} -> أسيوط | D14: =IF(B12="", "", COUNTIF(Orders!A2:A1000, B12)) -> 1 | E14: =IF(B12="", "", SUMIF(Orders!A2:A1000, B12, Orders!K2:K1000)) -> 160 | F14: =IF(B12="", "", SUMIF(Orders!A2:A1000, B12, Orders!N2:N1000)) -> 0
A16: سجل الطلبات الأخير للعميل (Client Recent Order History)
A17: كود الطلب (OrderID) | B17: التاريخ (Date) | C17: المنتج (Product) | D17: الكمية (Qty) | E17: الإجمالي (Total) | F17: المتبقي (Balance)
A18: =IFERROR(__xludf.DUMMYFUNCTION("IF(B12="""", """", IFERROR(QUERY(Orders!B2:N1000, ""select A, B, G, H, J, M where D = '"" & B12 & ""' order by B desc limit 5"", 0), ""لا توجد طلبات""))"),"لا توجد طلبات") -> لا توجد طلبات
H26: =IFERROR(__xludf.DUMMYFUNCTION("ARRAYFORMULA(SUM(SUMIF(Orders!G2:G1000, FILTER(#REF!, #REF! <> """"), Orders!K2:K1000)))"),0.0) -> 0

Sheet TempUnique
A1: {=UNIQUE(Clients!A:C)} -> العمود 1 | B1: Phone | C1: المحافظة
A2: الورشة | B2: 0
A3: Mr. Ramy | C3: الجيزة
A4: Hana | C4: القليوبية
A5: Tirvina | C5: القاهرة
A6: Youstina adel | C6: القاهرة
A7: مريم مجدي عبد الملك | C7: الغربية
A8: جوزيف | C8: القاهرة
A9: اسحب نبيل | C9: أسيوط
A10: دميانة ابراهيم | C10: الجيزة
A11: ابراهيم ميلاد | C11: أسيوط
A12: مينا سمير | C12: القاهرة
A13: بيشوي رمزي | C13: المنوفية
A14: حنان فرج | C14: القاهرة
... A49: سامي رضا | C49: بورسعيد
A50: سيفين
A51: مريم ملاك | C51: القاهرة
A52: رامي رفعت | C52: أسيوط
A53: مينا نبيل | C53: القاهرة
A54: عادل شفيق | C54: المنيا
A55: مارينا رمزي | C55: الإسكندرية
A56: يوستينا ميخائيل | C56: أسيوط
A57: مينا يسري | C57: القاهرة
A58: مينا محسن عياد | C58: المنيا
A59: ابرام عماد | C59: الجيزة
A60: امل | C60: القاهرة
A61: مارينا رؤوف | C61: القاهرة
A62: وائل مرزوق | C62: القاهرة
... A86: مروة | C86: الجيزة
A87: ابرام محسن | B87: 1200804440 | C87: المنيا
A88: چورچ ثروت | C88: القاهرة
A89: مارينا | C89: القاهرة
A90: ماريز سامح | B90: 1207708844 | C90: القاهرة
A91: فرج ملاك | B91: 1225238343 | C91: القاهرة
A92: اوليڤيا | B92: 1281274086 | C92: الجيزة
A93: صامويل صادق | C93: القاهرة
A94: مينا شوقي
A95: بيتر تقاوي | B95: 1275822147 | C95: القليوبية
A96: مرفت مرقص | B96: 1289239777 | C96: القاهرة
A97: ماريان يوسف | B97: 1223760341 | C97: المنيا
...

Sheet Financial Dashboard
J1: ملخص المبيعات
B2: لوحة التحكم المالية | J2: إجمالي المبيعات | K2: =SUM(Orders!K:K) -> 250102
J3: إجمالي المحصل | K3: =SUM(Orders!L:L) + SUM(Orders!Q:Q) -> 213066
J4: إجمالي المتبقي | K4: =SUM(Orders!S:S) -> 35798
J6: طرق الدفع
J7: Instapay | K7: =COUNTIF(Orders!M:M, "*Instapay*") + COUNTIF(Orders!R:R, "*Instapay*") -> 578
J8: Vodafone Cash | K8: =COUNTIF(Orders!M:M, "*VF*") + COUNTIF(Orders!R:R, "*VF*") -> 42
J9: Cash | K9: =COUNTIF(Orders!M:M, "*Cash*") + COUNTIF(Orders!R:R, "*Cash*") -> 44
J10: Visa / Post | K10: =COUNTIF(Orders!M:M, "*Visa post*") + COUNTIF(Orders!R:R, "*Visa post*") + COUNTIF(Orders!R:R, "*Postaa*") -> 152
J11: أخرى | K11: =COUNTA(Orders!M:M) + COUNTA(Orders!R:R) - SUM(K7:K10) - 2 -> 193
J13: التكاليف والمصروفات
J14: المصروفات العامة | K14: =SUM(Expenses!A2:A1000) -> 27096
J15: مصروفات إدارية | K15: =SUM('محفظتي'!AG2:AG1000) -> 54670
J16: تكلفة العمالة | K16: =SUMPRODUCT(Products!E2:E92, Products!H2:H92) -> 15569
J17: تكلفة الخامات | K17: =SUMPRODUCT(Products!C2:C92, Products!H2:H92) -> 141604

Sheet قيمة المخزن
A1: الصنف | B1: الكمية | C1: سعر التكلفة | D1: سعر البيع | E1: إجمالي التكلفة | F1: إجمالي قيمة البيع
A2: الإجمالي العام | B2: =SUM(B3:B1000) -> #REF! | E2: =SUM(E3:E1000) -> #REF! | F2: =SUM(F3:F1000) -> #REF!
A3: =IFERROR(__xludf.DUMMYFUNCTION("ARRAYFORMULA(LET(items, FILTER('Total Stock'!B3:B1000, 'Total Stock'!B3:B1000<>""""), qty, FILTER('Total Stock'!F3:F1000, 'Total Stock'!B3:B1000<>""""), cost, IFERROR(VLOOKUP(items, Products!A2:D1000, 3, FALSE), 0), price, IFERROR(VLOOKUP(items, Products!"&"A2:D1000, 4, FALSE), 0), HSTACK(items, qty, cost, price, qty*cost, qty*price)))"),"#REF!") -> #REF! | B3: =IFERROR(__xludf.DUMMYFUNCTION("""COMPUTED_VALUE"""),"#REF!") -> #REF! | C3: =IFERROR(__xludf.DUMMYFUNCTION("""COMPUTED_VALUE"""),0.0) -> 0 | D3: =IFERROR(__xludf.DUMMYFUNCTION("""COMPUTED_VALUE"""),0.0) -> 0 | E3: =IFERROR(__xludf.DUMMYFUNCTION("""COMPUTED_VALUE"""),"#REF!") -> #REF! | F3: =IFERROR(__xludf.DUMMYFUNCTION("""COMPUTED_VALUE"""),"#REF!") -> #REF!
